Workbook
Name NamaPerusahaan: Parameter!$C$3
Name TahunBuku: Parameter!$C$5
Name TarifPPh: Parameter!$C$6
Name Kel_Nama: Parameter!$B$12:$B$19
Name Kel_Masa: Parameter!$D$12:$D$19
Name Kat_Nama: Parameter!$B$23:$B$42
Name Kat_Umur: Parameter!$D$23:$D$42
Name Kat_Metode: Parameter!$E$23:$E$42
Name Kat_Kelompok: Parameter!$F$23:$F$42
Name Kat_AkunBeban: Parameter!$G$23:$G$42
Name Kat_AkunAkum: Parameter!$H$23:$H$42
Name L_KatAT: Parameter!$B$23:$B$32
Name L_KatATB: Parameter!$B$33:$B$42
Name L_MetodeAT: Parameter!$J$12:$J$15
Name L_MetodeATB: Parameter!$K$12:$K$15
Name L_MetodeFis: Parameter!$L$12:$L$14

Sheet Panduan
B1: PANDUAN TEMPLATE PENYUSUTAN & AMORTISASI
B2: KAP Sutrisno Hendrawanto Sukardi dan Rekan · dibuat dari SHSDesk Penyusutan & Amortisasi
B4: 1. DASAR REGULASI
B5: PSAK 216 – Aset Tetap | C5: Pengakuan, pengukuran, penyusutan sistematis selama umur manfaat; nilai residu, umur & metode ditelaah minimal tiap akhir tahun (perubahan = perubahan estimasi, prospektif – PSAK 208).
B6: PSAK 238 – Aset Takberwujud | C6: ATB umur terbatas diamortisasi (nilai residu umumnya nol); ATB umur tidak terbatas & goodwill tidak diamortisasi, diuji penurunan nilai tiap tahun (PSAK 236).
B7: PSAK 212 – Pajak Penghasilan | C7: Selisih nilai buku komersial vs nilai sisa buku fiskal = beda temporer → aset/liabilitas pajak tangguhan.
B8: UU PPh Pasal 11 & 11A s.t.d.d. UU HPP (UU 7/2021) | C8: Penyusutan harta berwujud & amortisasi harta tak berwujud; kelompok 1–4 (4/8/16/20 th), bangunan permanen 20 th / tidak permanen 10 th (garis lurus); WP dapat memakai masa manfaat sebenarnya bila > ketentuan (bangunan permanen & HTB).
B9: PMK 72 Tahun 2023 | C9: Jenis harta per kelompok, saat dimulainya penyusutan (bulan perolehan/pengerjaan selesai), dan tata cara penyusutan/amortisasi.
B11: 2. LANGKAH PENGGUNAAN
B12: Langkah 1 – Parameter | C12: Isi nama perusahaan, NPWP, Tahun Buku, dan tarif PPh. Sesuaikan tabel kategori (umur default, metode default, kelompok fiskal default, nama akun).
B13: Langkah 2 – Register Aset Tetap / Aset Takberwujud | C13: Isi kolom B–R (latar kuning). Kolom I, J, N, P boleh dikosongkan → otomatis memakai default kategori. Unit Produksi: isi kolom K–M. Pelepasan/penjualan: isi kolom Q & R.
B14: Langkah 3 – Cek Validasi | C14: Kolom BH harus 'OK'. Pesan lain menandakan input belum lengkap/tidak sesuai ketentuan (mis. bangunan dengan saldo menurun).
B15: Langkah 4 – Jadwal Bulanan | C15: Beban per bulan terisi otomatis untuk jurnal bulanan; kolom Selisih harus 0.
B16: Langkah 5 – Rekap & Jurnal | C16: Rekap komersial per kategori, rekap fiskal per kelompok (dasar Lampiran Khusus 1A SPT 1771), koreksi fiskal, pajak tangguhan, dan draf jurnal.
B17: Unggah ke sistem | C17: Workbook ini dapat diunggah kembali ke SHSDesk Penyusutan & Amortisasi (tombol Unggah Excel).
B19: 3. METODE & KONVENSI PERHITUNGAN
B20: Konvensi bulan | C20: Penyusutan/amortisasi dimulai pada bulan perolehan (bulan penuh) dan dihitung sampai dengan bulan pelepasan.
B21: Garis Lurus | C21: Komersial: (Harga Perolehan − Nilai Residu) ÷ (Umur × 12) per bulan. Fiskal: Harga Perolehan × tarif garis lurus (nilai sisa nol).
B22: Saldo Menurun | C22: Tarif = 2 ÷ umur (fiskal: 50%/25%/12,5%/10%). Tahun pertama proporsional bulan. Pada tahun berakhirnya masa manfaat, sisa nilai buku disusutkan sekaligus (fiskal) / sampai nilai residu (komersial). Tidak boleh untuk bangunan (fiskal).
B23: Unit Produksi | C23: Komersial saja: (Harga Perolehan − Nilai Residu) × Unit Tahun Berjalan ÷ Total Kapasitas. Fiskal tetap memakai garis lurus/saldo menurun.
B24: Pelepasan | C24: Laba/(rugi) = Nilai Pelepasan − Nilai Buku saat dilepas, dihitung terpisah komersial & fiskal (Pasal 11 ayat 8 UU PPh); selisihnya menjadi koreksi fiskal.
B25: Koreksi fiskal | C25: (+) Koreksi positif bila beban komersial > fiskal; (−) koreksi negatif bila sebaliknya.
B27: 4. KODE WARNA
B28: Teks biru / latar kuning | C28: Input yang diisi pengguna
B29: Teks hitam | C29: Formula otomatis – jangan ditimpa
B30: Kolom abu-abu (Y:AK) | C30: Kolom bantu perhitungan (dikelompokkan; klik −/+ untuk menyembunyikan/menampilkan)
B32: 5. BATASAN
B33: Catatan | C33: Template tidak menghitung revaluasi (model revaluasi PSAK 216), rugi penurunan nilai (PSAK 236), aset hak guna (PSAK 116), maupun fasilitas/ketentuan khusus sektor tertentu. Kapasitas 200 baris per register. Hasil perlu ditelaah oleh akuntan/konsultan pajak.

Sheet Parameter
B1: PARAMETER & TABEL REFERENSI
B3: Nama Perusahaan | C3: Nama Perusahaan
B4: NPWP
B5: Tahun Buku | C5: 2026 | D5: Ubah tahun ini → seluruh perhitungan otomatis diperbarui
B6: Tarif PPh Badan | C6: 0.22 | D6: Pasal 17 ayat (1) huruf b UU PPh s.t.d.d. UU HPP (fasilitas Pasal 31E tidak diperhitungkan)
B7: Awal Periode | C7: =DATE(C5,1,1) -> 46023
B8: Akhir Periode | C8: =DATE(C5,12,31) -> 46387
B10: A. KELOMPOK HARTA FISKAL (UU PPh Pasal 11 & 11A s.t.d.d. UU HPP; PMK 72 Tahun 2023) | J10: C. DAFTAR PILIHAN (DROPDOWN)
B11: Kelompok Harta | C11: Jenis Harta | D11: Masa Manfaat (Tahun) | E11: Tarif Garis Lurus | F11: Tarif Saldo Menurun | G11: Keterangan | J11: Metode Komersial - Aset Tetap | K11: Metode Komersial - ATB | L11: Metode Fiskal
B12: Kelompok 1 | C12: Bukan bangunan / HTB | D12: 4 | E12: =IF(N(D12)>0,1/D12,0) -> 0.25 | F12: =IF(N(D12)>0,2/D12,0) -> 0.5 | G12: Pasal 11 ayat (6) & Pasal 11A ayat (2) | J12: Garis Lurus | K12: Garis Lurus | L12: Garis Lurus
B13: Kelompok 2 | C13: Bukan bangunan / HTB | D13: 8 | E13: =IF(N(D13)>0,1/D13,0) -> 0.125 | F13: =IF(N(D13)>0,2/D13,0) -> 0.25 | G13: Pasal 11 ayat (6) & Pasal 11A ayat (2) | J13: Saldo Menurun | K13: Saldo Menurun | L13: Saldo Menurun
B14: Kelompok 3 | C14: Bukan bangunan / HTB | D14: 16 | E14: =IF(N(D14)>0,1/D14,0) -> 0.0625 | F14: =IF(N(D14)>0,2/D14,0) -> 0.125 | G14: Pasal 11 ayat (6) & Pasal 11A ayat (2) | J14: Unit Produksi | K14: Unit Produksi | L14: Tidak Disusutkan
B15: Kelompok 4 | C15: Bukan bangunan / HTB | D15: 20 | E15: =IF(N(D15)>0,1/D15,0) -> 0.05 | F15: =IF(N(D15)>0,2/D15,0) -> 0.1 | G15: Pasal 11 ayat (6) & Pasal 11A ayat (2) | J15: Tidak Disusutkan | K15: Tidak Diamortisasi
B16: Bangunan Permanen | C16: Bangunan | D16: 20 | E16: =IF(N(D16)>0,1/D16,0) -> 0.05 | F16: =0 -> 0 | G16: Wajib garis lurus; dapat > 20 th sesuai masa manfaat sebenarnya (UU HPP)
B17: Bangunan Tidak Permanen | C17: Bangunan | D17: 10 | E17: =IF(N(D17)>0,1/D17,0) -> 0.1 | F17: =0 -> 0 | G17: Wajib garis lurus
B18: Masa Manfaat Sebenarnya | C18: Bangunan permanen / HTB > 20 th | E18: =IF(N(D18)>0,1/D18,0) -> 0 | F18: =IF(N(D18)>0,2/D18,0) -> 0 | G18: Isi kolom 'Masa Manfaat Fiskal Sebenarnya' pada register (UU HPP)
B19: Tidak Disusutkan | C19: Tanah / harta tidak disusutkan | D19: 0 | E19: =IF(N(D19)>0,1/D19,0) -> 0 | F19: =IF(N(D19)>0,2/D19,0) -> 0 | G19: Tanah hak milik/HGB tidak disusutkan (kecuali tanah untuk usaha tertentu)
B21: B. KATEGORI ASET (KOMERSIAL – PSAK 216 / PSAK 238) & DEFAULT PENGISIAN OTOMATIS
B22: Kategori | C22: Jenis | D22: Umur Ekonomis Default (Tahun) | E22: Metode Komersial Default | F22: Kelompok Fiskal Default | G22: Akun Beban | H22: Akun Akumulasi
B23: Tanah | C23: Aset Tetap | D23: 0 | E23: Tidak Disusutkan | F23: Tidak Disusutkan | G23: - | H23: -
B24: Bangunan | C24: Aset Tetap | D24: 20 | E24: Garis Lurus | F24: Bangunan Permanen | G24: Beban Penyusutan - Bangunan | H24: Akumulasi Penyusutan - Bangunan
B25: Kendaraan | C25: Aset Tetap | D25: 8 | E25: Garis Lurus | F25: Kelompok 2 | G25: Beban Penyusutan - Kendaraan | H25: Akumulasi Penyusutan - Kendaraan
B26: Mesin & Peralatan | C26: Aset Tetap | D26: 10 | E26: Garis Lurus | F26: Kelompok 3 | G26: Beban Penyusutan - Mesin & Peralatan | H26: Akumulasi Penyusutan - Mesin & Peralatan
B27: Komputer & IT | C27: Aset Tetap | D27: 4 | E27: Garis Lurus | F27: Kelompok 1 | G27: Beban Penyusutan - Komputer & IT | H27: Akumulasi Penyusutan - Komputer & IT
B28: Inventaris Kantor | C28: Aset Tetap | D28: 4 | E28: Garis Lurus | F28: Kelompok 1 | G28: Beban Penyusutan - Inventaris Kantor | H28: Akumulasi Penyusutan - Inventaris Kantor
C29: Aset Tetap
C30: Aset Tetap
C31: Aset Tetap
C32: Aset Tetap
B33: Perangkat Lunak | C33: Aset Takberwujud | D33: 4 | E33: Garis Lurus | F33: Kelompok 1 | G33: Beban Amortisasi - Perangkat Lunak | H33: Akumulasi Amortisasi - Perangkat Lunak
B34: Lisensi & Waralaba | C34: Aset Takberwujud | D34: 10 | E34: Garis Lurus | F34: Kelompok 3 | G34: Beban Amortisasi - Lisensi & Waralaba | H34: Akumulasi Amortisasi - Lisensi & Waralaba
B35: Hak Paten | C35: Aset Takberwujud | D35: 10 | E35: Garis Lurus | F35: Kelompok 3 | G35: Beban Amortisasi - Hak Paten | H35: Akumulasi Amortisasi - Hak Paten
B36: Merek Dagang | C36: Aset Takberwujud | D36: 0 | E36: Tidak Diamortisasi | F36: Kelompok 4 | G36: Beban Amortisasi - Merek Dagang | H36: Akumulasi Amortisasi - Merek Dagang
B37: Goodwill | C37: Aset Takberwujud | D37: 0 | E37: Tidak Diamortisasi | F37: Kelompok 4 | G37: Beban Amortisasi - Goodwill | H37: Akumulasi Amortisasi - Goodwill
C38: Aset Takberwujud
C39: Aset Takberwujud
C40: Aset Takberwujud
C41: Aset Takberwujud
C42: Aset Takberwujud
B43: Baris kosong dapat diisi kategori tambahan. Umur 0 + 'Tidak Disusutkan/Diamortisasi' = tidak disusutkan (mis. tanah, ATB umur tidak terbatas – diuji penurunan nilai PSAK 236).

Sheet Aset Tetap
A1: REGISTER ASET TETAP
A2: =NamaPerusahaan -> Nama Perusahaan
A3: ="Tahun Buku "&TahunBuku&" | Komersial: PSAK 216 | Fiskal: Pasal 11 UU PPh s.t.d.d. UU HPP & PMK 72/2023" -> Tahun Buku 2026 | Komersial: PSAK 216 | Fiskal: Pasal 11 UU PPh s.t.d.d. UU HPP & PMK 72/2023
A4: Teks biru/latar kuning = input. Teks hitam = formula otomatis (jangan diubah). Kolom Y:AK = kolom bantu (dikelompokkan, dapat diciutkan dengan tombol −/+).
A5: INPUT DATA ASET | S5: PARAMETER EFEKTIF (OTOMATIS) | Y5: KOLOM BANTU PERHITUNGAN | AL5: KOMERSIAL (PSAK 216) | AV5: FISKAL (UU PPh) | BB5: REKONSILIASI FISKAL & PAJAK TANGGUHAN (PSAK 212)
A6: No | B6: Kode Aset | C6: Nama Aset | D6: Kategori | E6: Lokasi / Departemen | F6: Tanggal Perolehan | G6: Harga Perolehan (Rp) | H6: Nilai Residu Komersial (Rp) | I6: Metode Komersial (kosong = default) | J6: Umur Ekonomis Komersial (Th) (kosong = default) | K6: Total Kapasitas Unit (khusus Unit Produksi) | L6: Akum. Unit s.d. Tahun Lalu | M6: Unit Tahun Berjalan | N6: Kelompok Fiskal (kosong = default) | O6: Masa Manfaat Fiskal Sebenarnya (Th) | P6: Metode Fiskal (kosong = default) | Q6: Tanggal Pelepasan / Penjualan | R6: Nilai Pelepasan / Harga Jual (Rp) | S6: Metode Komersial | T6: Umur Komersial (Th) | U6: Kelompok Fiskal | V6: Masa Manfaat Fiskal (Th) | W6: Metode Fiskal | X6: Status | Y6: Idx Bulan Perolehan | Z6: Idx Bulan Pelepasan | AA6: Flag Dimiliki Awal Thn | AB6: Flag Perolehan Thn Ini | AC6: Flag Pelepasan Thn Ini | AD6: NB Komersial Teoretis Akhir Thn Lalu | AE6: NB Komersial Teoretis Akhir Thn Ini | AF6: Bulan Aktif Komersial | AG6: Bulan Aktif Komersial s.d. Pelepasan | AH6: NSB Fiskal Teoretis Akhir Thn Lalu | AI6: NSB Fiskal Teoretis Akhir Thn Ini | AJ6: Bulan Aktif Fiskal | AK6: Bulan Aktif Fiskal s.d. Pelepasan | AL6: Harga Perolehan Awal Tahun | AM6: Penambahan | AN6: Pengurangan (Pelepasan) | AO6: Harga Perolehan Akhir Tahun | AP6: Akum. Penyusutan Awal Tahun | AQ6: Beban Penyusutan Tahun Berjalan | AR6: Akum. Penyusutan atas Pelepasan | AS6: Akum. Penyusutan Akhir Tahun | AT6: Nilai Buku Akhir Tahun | AU6: Laba / (Rugi) Pelepasan Komersial | AV6: Akum. Penyusutan Fiskal Awal Tahun | AW6: Penyusutan Fiskal Tahun Berjalan | AX6: Akum. Fiskal atas Pelepasan | AY6: Akum. Penyusutan Fiskal Akhir Tahun | AZ6: Nilai Sisa Buku Fiskal Akhir Tahun | BA6: Laba / (Rugi) Pelepasan Fiskal | BB6: Koreksi Fiskal Penyusutan (+/−) | BC6: Koreksi Fiskal Laba/Rugi Pelepasan (+/−) | BD6: Total Koreksi Fiskal (+/−) | BE6: Beda Temporer Awal Tahun (NB Kom − NSB Fis) | BF6: Beda Temporer Akhir Tahun (NB Kom − NSB Fis) | BG6: Pajak Tangguhan Akhir (+ Liabilitas / − Aset) | BH6: Cek Validasi
A7: =IF($B7="","",ROW()-6) | S7: =IF($B7="","",IF($I7<>"",$I7,IFERROR(INDEX(Kat_Metode,MATCH($D7,Kat_Nama,0)),""))) | T7: =IF($B7="","",IF($J7<>"",$J7,IFERROR(INDEX(Kat_Umur,MATCH($D7,Kat_Nama,0)),0))) | U7: =IF($B7="","",IF($N7<>"",$N7,IFERROR(INDEX(Kat_Kelompok,MATCH($D7,Kat_Nama,0)),""))) | V7: =IF($B7="","",IF($U7="Masa Manfaat Sebenarnya",N($O7),IFERROR(INDEX(Kel_Masa,MATCH($U7,Kel_Nama,0)),0))) | W7: =IF($B7="","",IF($P7<>"",$P7,IF(OR($U7="Tidak Disusutkan",$V7=0),"Tidak Disusutkan","Garis Lurus"))) | X7: =IF($B7="","",IF($Y7>TahunBuku*12+12,"Belum Diperoleh",IF($Z7<=TahunBuku*12,"Dilepas (thn lalu)",IF($AC7=1,"Dilepas thn ini",IF($AB7=1,"Perolehan baru","Aktif"))))) | Y7: =IF($B7="","",YEAR($F7)*12+MONTH($F7)) | Z7: =IF($B7="","",IF($Q7="",99999,YEAR($Q7)*12+MONTH($Q7))) | AA7: =IF($B7="","",--AND($Y7<=TahunBuku*12,$Z7>TahunBuku*12)) | AB7: =IF($B7="","",--AND($Y7>TahunBuku*12,$Y7<=TahunBuku*12+12)) | AC7: =IF($B7="","",--AND($Z7>TahunBuku*12,$Z7<=TahunBuku*12+12,$Y7<=$Z7)) | AD7: =IF($B7="","",IFERROR(IF($S7="Garis Lurus",$G7-($G7-$H7)*MIN($T7*12,MAX(0,TahunBuku*12-$Y7+1))/($T7*12),IF($S7="Saldo Menurun",IF(TahunBuku-1<YEAR($F7),$G7,IF(TahunBuku-1>=INT(($Y7+$T7*12-2)/12),$H7,MAX($H7,$G7*(1-2/$T7*(13-MONTH($F7))/12)*(1-2/$T7)^(TahunBuku-1-YEAR($F7))))),IF($S7="Unit Produksi",$G7-($G7-$H7)*MIN(1,N($L7)/$K7),$G7))),$G7)) | AE7: =IF($B7="","",IFERROR(IF($S7="Garis Lurus",$G7-($G7-$H7)*MIN($T7*12,MAX(0,TahunBuku*12+12-$Y7+1))/($T7*12),IF($S7="Saldo Menurun",IF(TahunBuku<YEAR($F7),$G7,IF(TahunBuku>=INT(($Y7+$T7*12-2)/12),$H7,MAX($H7,$G7*(1-2/$T7*(13-MONTH($F7))/12)*(1-2/$T7)^(TahunBuku-YEAR($F7))))),IF($S7="Unit Produksi",$G7-($G7-$H7)*MIN(1,(N($L7)+N($M7))/$K7),$G7))),$G7)) | AF7: =IF($B7="","",IF(OR($S7="Garis Lurus",$S7="Saldo Menurun",$S7="Unit Produksi"),MAX(0,IF($S7="Unit Produksi",TahunBuku*12+12,MIN(TahunBuku*12+12,$Y7+$T7*12-1))-MAX(TahunBuku*12+1,$Y7)+1),0)) | AG7: =IF($B7="","",IF(OR($S7="Garis Lurus",$S7="Saldo Menurun",$S7="Unit Produksi"),MAX(0,MIN($Z7,IF($S7="Unit Produksi",TahunBuku*12+12,MIN(TahunBuku*12+12,$Y7+$T7*12-1)))-MAX(TahunBuku*12+1,$Y7)+1),0)) | AH7: =IF($B7="","",IFERROR(IF($W7="Garis Lurus",$G7*(1-MIN($V7*12,MAX(0,TahunBuku*12-$Y7+1))/($V7*12)),IF($W7="Saldo Menurun",IF(TahunBuku-1<YEAR($F7),$G7,IF(TahunBuku-1>=INT(($Y7+$V7*12-2)/12),0,$G7*(1-2/$V7*(13-MONTH($F7))/12)*(1-2/$V7)^(TahunBuku-1-YEAR($F7)))),$G7)),$G7)) | AI7: =IF($B7="","",IFERROR(IF($W7="Garis Lurus",$G7*(1-MIN($V7*12,MAX(0,TahunBuku*12+12-$Y7+1))/($V7*12)),IF($W7="Saldo Menurun",IF(TahunBuku<YEAR($F7),$G7,IF(TahunBuku>=INT(($Y7+$V7*12-2)/12),0,$G7*(1-2/$V7*(13-MONTH($F7))/12)*(1-2/$V7)^(TahunBuku-YEAR($F7)))),$G7)),$G7)) | AJ7: =IF($B7="","",IF(OR($W7="Garis Lurus",$W7="Saldo Menurun"),MAX(0,MIN(TahunBuku*12+12,$Y7+$V7*12-1)-MAX(TahunBuku*12+1,$Y7)+1),0)) | AK7: =IF($B7="","",IF(OR($W7="Garis Lurus",$W7="Saldo Menurun"),MAX(0,MIN($Z7,TahunBuku*12+12,$Y7+$V7*12-1)-MAX(TahunBuku*12+1,$Y7)+1),0)) | AL7: =IF($B7="","",$G7*$AA7) | AM7: =IF($B7="","",$G7*$AB7) | AN7: =IF($B7="","",$G7*$AC7) | AO7: =IF($B7="","",AL7+AM7-AN7) | AP7: =IF($B7="","",($G7-$AD7)*$AA7) | AQ7: =IF($B7="","",IF($AF7=0,0,($AD7-$AE7)*$AG7/$AF7)*MAX($AA7,$AB7)) | AR7: =IF($B7="","",(AP7+AQ7)*$AC7) | AS7: =IF($B7="","",AP7+AQ7-AR7) | AT7: =IF($B7="","",AO7-AS7) | AU7: =IF($B7="","",IF($AC7=1,N($R7)-($G7-AR7),0)) | AV7: =IF($B7="","",($G7-$AH7)*$AA7) | AW7: =IF($B7="","",IF($AJ7=0,0,($AH7-$AI7)*$AK7/$AJ7)*MAX($AA7,$AB7)) | AX7: =IF($B7="","",(AV7+AW7)*$AC7) | AY7: =IF($B7="","",AV7+AW7-AX7) | AZ7: =IF($B7="","",AO7-AY7) | BA7: =IF($B7="","",IF($AC7=1,N($R7)-($G7-AX7),0)) | BB7: =IF($B7="","",ROUND(AQ7-AW7,0)) | BC7: =IF($B7="","",ROUND(BA7-AU7,0)) | BD7: =IF($B7="","",BB7+BC7) | BE7: =IF($B7="","",ROUND(AV7-AP7,0)) | BF7: =IF($B7="","",ROUND(AT7-AZ7,0)) | BG7: =IF($B7="","",ROUND(BF7*TarifPPh,0)) | BH7: =IF($B7="","",IF($D7="","Kategori kosong",IF($F7="","Tgl perolehan kosong",IF(N($H7)>$G7,"Residu > harga perolehan",IF(AND(LEFT($U7,8)="Bangunan",$W7="Saldo Menurun"),"Bangunan wajib Garis Lurus (Ps.11 UU PPh)",IF(AND($S7="Unit Produksi",N($K7)=0),"Isi kapasitas unit",IF(AND(OR($S7="Garis Lurus",$S7="Saldo Menurun"),N($T7)<=0),"Umur komersial kosong",IF(AND(OR($W7="Garis Lurus",$W7="Saldo Menurun"),N($V7)<=0),"Masa manfaat fiskal kosong",IF(AND($Q7<>"",$Q7<$F7),"Tgl pelepasan < perolehan","OK")))))))))
A8: =IF($B8="","",ROW()-6) | S8: =IF($B8="","",IF($I8<>"",$I8,IFERROR(INDEX(Kat_Metode,MATCH($D8,Kat_Nama,0)),""))) | T8: =IF($B8="","",IF($J8<>"",$J8,IFERROR(INDEX(Kat_Umur,MATCH($D8,Kat_Nama,0)),0))) | U8: =IF($B8="","",IF($N8<>"",$N8,IFERROR(INDEX(Kat_Kelompok,MATCH($D8,Kat_Nama,0)),""))) | V8: =IF($B8="","",IF($U8="Masa Manfaat Sebenarnya",N($O8),IFERROR(INDEX(Kel_Masa,MATCH($U8,Kel_Nama,0)),0))) | W8: =IF($B8="","",IF($P8<>"",$P8,IF(OR($U8="Tidak Disusutkan",$V8=0),"Tidak Disusutkan","Garis Lurus"))) | X8: =IF($B8="","",IF($Y8>TahunBuku*12+12,"Belum Diperoleh",IF($Z8<=TahunBuku*12,"Dilepas (thn lalu)",IF($AC8=1,"Dilepas thn ini",IF($AB8=1,"Perolehan baru","Aktif"))))) | Y8: =IF($B8="","",YEAR($F8)*12+MONTH($F8)) | Z8: =IF($B8="","",IF($Q8="",99999,YEAR($Q8)*12+MONTH($Q8))) | AA8: =IF($B8="","",--AND($Y8<=TahunBuku*12,$Z8>TahunBuku*12)) | AB8: =IF($B8="","",--AND($Y8>TahunBuku*12,$Y8<=TahunBuku*12+12)) | AC8: =IF($B8="","",--AND($Z8>TahunBuku*12,$Z8<=TahunBuku*12+12,$Y8<=$Z8)) | AD8: =IF($B8="","",IFERROR(IF($S8="Garis Lurus",$G8-($G8-$H8)*MIN($T8*12,MAX(0,TahunBuku*12-$Y8+1))/($T8*12),IF($S8="Saldo Menurun",IF(TahunBuku-1<YEAR($F8),$G8,IF(TahunBuku-1>=INT(($Y8+$T8*12-2)/12),$H8,MAX($H8,$G8*(1-2/$T8*(13-MONTH($F8))/12)*(1-2/$T8)^(TahunBuku-1-YEAR($F8))))),IF($S8="Unit Produksi",$G8-($G8-$H8)*MIN(1,N($L8)/$K8),$G8))),$G8)) | AE8: =IF($B8="","",IFERROR(IF($S8="Garis Lurus",$G8-($G8-$H8)*MIN($T8*12,MAX(0,TahunBuku*12+12-$Y8+1))/($T8*12),IF($S8="Saldo Menurun",IF(TahunBuku<YEAR($F8),$G8,IF(TahunBuku>=INT(($Y8+$T8*12-2)/12),$H8,MAX($H8,$G8*(1-2/$T8*(13-MONTH($F8))/12)*(1-2/$T8)^(TahunBuku-YEAR($F8))))),IF($S8="Unit Produksi",$G8-($G8-$H8)*MIN(1,(N($L8)+N($M8))/$K8),$G8))),$G8)) | AF8: =IF($B8="","",IF(OR($S8="Garis Lurus",$S8="Saldo Menurun",$S8="Unit Produksi"),MAX(0,IF($S8="Unit Produksi",TahunBuku*12+12,MIN(TahunBuku*12+12,$Y8+$T8*12-1))-MAX(TahunBuku*12+1,$Y8)+1),0)) | AG8: =IF($B8="","",IF(OR($S8="Garis Lurus",$S8="Saldo Menurun",$S8="Unit Produksi"),MAX(0,MIN($Z8,IF($S8="Unit Produksi",TahunBuku*12+12,MIN(TahunBuku*12+12,$Y8+$T8*12-1)))-MAX(TahunBuku*12+1,$Y8)+1),0)) | AH8: =IF($B8="","",IFERROR(IF($W8="Garis Lurus",$G8*(1-MIN($V8*12,MAX(0,TahunBuku*12-$Y8+1))/($V8*12)),IF($W8="Saldo Menurun",IF(TahunBuku-1<YEAR($F8),$G8,IF(TahunBuku-1>=INT(($Y8+$V8*12-2)/12),0,$G8*(1-2/$V8*(13-MONTH($F8))/12)*(1-2/$V8)^(TahunBuku-1-YEAR($F8)))),$G8)),$G8)) | AI8: =IF($B8="","",IFERROR(IF($W8="Garis Lurus",$G8*(1-MIN($V8*12,MAX(0,TahunBuku*12+12-$Y8+1))/($V8*12)),IF($W8="Saldo Menurun",IF(TahunBuku<YEAR($F8),$G8,IF(TahunBuku>=INT(($Y8+$V8*12-2)/12),0,$G8*(1-2/$V8*(13-MONTH($F8))/12)*(1-2/$V8)^(TahunBuku-YEAR($F8)))),$G8)),$G8)) | AJ8: =IF($B8="","",IF(OR($W8="Garis Lurus",$W8="Saldo Menurun"),MAX(0,MIN(TahunBuku*12+12,$Y8+$V8*12-1)-MAX(TahunBuku*12+1,$Y8)+1),0)) | AK8: =IF($B8="","",IF(OR($W8="Garis Lurus",$W8="Saldo Menurun"),MAX(0,MIN($Z8,TahunBuku*12+12,$Y8+$V8*12-1)-MAX(TahunBuku*12+1,$Y8)+1),0)) | AL8: =IF($B8="","",$G8*$AA8) | AM8: =IF($B8="","",$G8*$AB8) | AN8: =IF($B8="","",$G8*$AC8) | AO8: =IF($B8="","",AL8+AM8-AN8) | AP8: =IF($B8="","",($G8-$AD8)*$AA8) | AQ8: =IF($B8="","",IF($AF8=0,0,($AD8-$AE8)*$AG8/$AF8)*MAX($AA8,$AB8)) | AR8: =IF($B8="","",(AP8+AQ8)*$AC8) | AS8: =IF($B8="","",AP8+AQ8-AR8) | AT8: =IF($B8="","",AO8-AS8) | AU8: =IF($B8="","",IF($AC8=1,N($R8)-($G8-AR8),0)) | AV8: =IF($B8="","",($G8-$AH8)*$AA8) | AW8: =IF($B8="","",IF($AJ8=0,0,($AH8-$AI8)*$AK8/$AJ8)*MAX($AA8,$AB8)) | AX8: =IF($B8="","",(AV8+AW8)*$AC8) | AY8: =IF($B8="","",AV8+AW8-AX8) | AZ8: =IF($B8="","",AO8-AY8) | BA8: =IF($B8="","",IF($AC8=1,N($R8)-($G8-AX8),0)) | BB8: =IF($B8="","",ROUND(AQ8-AW8,0)) | BC8: =IF($B8="","",ROUND(BA8-AU8,0)) | BD8: =IF($B8="","",BB8+BC8) | BE8: =IF($B8="","",ROUND(AV8-AP8,0)) | BF8: =IF($B8="","",ROUND(AT8-AZ8,0)) | BG8: =IF($B8="","",ROUND(BF8*TarifPPh,0)) | BH8: =IF($B8="","",IF($D8="","Kategori kosong",IF($F8="","Tgl perolehan kosong",IF(N($H8)>$G8,"Residu > harga perolehan",IF(AND(LEFT($U8,8)="Bangunan",$W8="Saldo Menurun"),"Bangunan wajib Garis Lurus (Ps.11 UU PPh)",IF(AND($S8="Unit Produksi",N($K8)=0),"Isi kapasitas unit",IF(AND(OR($S8="Garis Lurus",$S8="Saldo Menurun"),N($T8)<=0),"Umur komersial kosong",IF(AND(OR($W8="Garis Lurus",$W8="Saldo Menurun"),N($V8)<=0),"Masa manfaat fiskal kosong",IF(AND($Q8<>"",$Q8<$F8),"Tgl pelepasan < perolehan","OK")))))))))
A9: =IF($B9="","",ROW()-6) | S9: =IF($B9="","",IF($I9<>"",$I9,IFERROR(INDEX(Kat_Metode,MATCH($D9,Kat_Nama,0)),""))) | T9: =IF($B9="","",IF($J9<>"",$J9,IFERROR(INDEX(Kat_Umur,MATCH($D9,Kat_Nama,0)),0))) | U9: =IF($B9="","",IF($N9<>"",$N9,IFERROR(INDEX(Kat_Kelompok,MATCH($D9,Kat_Nama,0)),""))) | V9: =IF($B9="","",IF($U9="Masa Manfaat Sebenarnya",N($O9),IFERROR(INDEX(Kel_Masa,MATCH($U9,Kel_Nama,0)),0))) | W9: =IF($B9="","",IF($P9<>"",$P9,IF(OR($U9="Tidak Disusutkan",$V9=0),"Tidak Disusutkan","Garis Lurus"))) | X9: =IF($B9="","",IF($Y9>TahunBuku*12+12,"Belum Diperoleh",IF($Z9<=TahunBuku*12,"Dilepas (thn lalu)",IF($AC9=1,"Dilepas thn ini",IF($AB9=1,"Perolehan baru","Aktif"))))) | Y9: =IF($B9="","",YEAR($F9)*12+MONTH($F9)) | Z9: =IF($B9="","",IF($Q9="",99999,YEAR($Q9)*12+MONTH($Q9))) | AA9: =IF($B9="","",--AND($Y9<=TahunBuku*12,$Z9>TahunBuku*12)) | AB9: =IF($B9="","",--AND($Y9>TahunBuku*12,$Y9<=TahunBuku*12+12)) | AC9: =IF($B9="","",--AND($Z9>TahunBuku*12,$Z9<=TahunBuku*12+12,$Y9<=$Z9)) | AD9: =IF($B9="","",IFERROR(IF($S9="Garis Lurus",$G9-($G9-$H9)*MIN($T9*12,MAX(0,TahunBuku*12-$Y9+1))/($T9*12),IF($S9="Saldo Menurun",IF(TahunBuku-1<YEAR($F9),$G9,IF(TahunBuku-1>=INT(($Y9+$T9*12-2)/12),$H9,MAX($H9,$G9*(1-2/$T9*(13-MONTH($F9))/12)*(1-2/$T9)^(TahunBuku-1-YEAR($F9))))),IF($S9="Unit Produksi",$G9-($G9-$H9)*MIN(1,N($L9)/$K9),$G9))),$G9)) | AE9: =IF($B9="","",IFERROR(IF($S9="Garis Lurus",$G9-($G9-$H9)*MIN($T9*12,MAX(0,TahunBuku*12+12-$Y9+1))/($T9*12),IF($S9="Saldo Menurun",IF(TahunBuku<YEAR($F9),$G9,IF(TahunBuku>=INT(($Y9+$T9*12-2)/12),$H9,MAX($H9,$G9*(1-2/$T9*(13-MONTH($F9))/12)*(1-2/$T9)^(TahunBuku-YEAR($F9))))),IF($S9="Unit Produksi",$G9-($G9-$H9)*MIN(1,(N($L9)+N($M9))/$K9),$G9))),$G9)) | AF9: =IF($B9="","",IF(OR($S9="Garis Lurus",$S9="Saldo Menurun",$S9="Unit Produksi"),MAX(0,IF($S9="Unit Produksi",TahunBuku*12+12,MIN(TahunBuku*12+12,$Y9+$T9*12-1))-MAX(TahunBuku*12+1,$Y9)+1),0)) | AG9: =IF($B9="","",IF(OR($S9="Garis Lurus",$S9="Saldo Menurun",$S9="Unit Produksi"),MAX(0,MIN($Z9,IF($S9="Unit Produksi",TahunBuku*12+12,MIN(TahunBuku*12+12,$Y9+$T9*12-1)))-MAX(TahunBuku*12+1,$Y9)+1),0)) | AH9: =IF($B9="","",IFERROR(IF($W9="Garis Lurus",$G9*(1-MIN($V9*12,MAX(0,TahunBuku*12-$Y9+1))/($V9*12)),IF($W9="Saldo Menurun",IF(TahunBuku-1<YEAR($F9),$G9,IF(TahunBuku-1>=INT(($Y9+$V9*12-2)/12),0,$G9*(1-2/$V9*(13-MONTH($F9))/12)*(1-2/$V9)^(TahunBuku-1-YEAR($F9)))),$G9)),$G9)) | AI9: =IF($B9="","",IFERROR(IF($W9="Garis Lurus",$G9*(1-MIN($V9*12,MAX(0,TahunBuku*12+12-$Y9+1))/($V9*12)),IF($W9="Saldo Menurun",IF(TahunBuku<YEAR($F9),$G9,IF(TahunBuku>=INT(($Y9+$V9*12-2)/12),0,$G9*(1-2/$V9*(13-MONTH($F9))/12)*(1-2/$V9)^(TahunBuku-YEAR($F9)))),$G9)),$G9)) | AJ9: =IF($B9="","",IF(OR($W9="Garis Lurus",$W9="Saldo Menurun"),MAX(0,MIN(TahunBuku*12+12,$Y9+$V9*12-1)-MAX(TahunBuku*12+1,$Y9)+1),0)) | AK9: =IF($B9="","",IF(OR($W9="Garis Lurus",$W9="Saldo Menurun"),MAX(0,MIN($Z9,TahunBuku*12+12,$Y9+$V9*12-1)-MAX(TahunBuku*12+1,$Y9)+1),0)) | AL9: =IF($B9="","",$G9*$AA9) | AM9: =IF($B9="","",$G9*$AB9) | AN9: =IF($B9="","",$G9*$AC9) | AO9: =IF($B9="","",AL9+AM9-AN9) | AP9: =IF($B9="","",($G9-$AD9)*$AA9) | AQ9: =IF($B9="","",IF($AF9=0,0,($AD9-$AE9)*$AG9/$AF9)*MAX($AA9,$AB9)) | AR9: =IF($B9="","",(AP9+AQ9)*$AC9) | AS9: =IF($B9="","",AP9+AQ9-AR9) | AT9: =IF($B9="","",AO9-AS9) | AU9: =IF($B9="","",IF($AC9=1,N($R9)-($G9-AR9),0)) | AV9: =IF($B9="","",($G9-$AH9)*$AA9) | AW9: =IF($B9="","",IF($AJ9=0,0,($AH9-$AI9)*$AK9/$AJ9)*MAX($AA9,$AB9)) | AX9: =IF($B9="","",(AV9+AW9)*$AC9) | AY9: =IF($B9="","",AV9+AW9-AX9) | AZ9: =IF($B9="","",AO9-AY9) | BA9: =IF($B9="","",IF($AC9=1,N($R9)-($G9-AX9),0)) | BB9: =IF($B9="","",ROUND(AQ9-AW9,0)) | BC9: =IF($B9="","",ROUND(BA9-AU9,0)) | BD9: =IF($B9="","",BB9+BC9) | BE9: =IF($B9="","",ROUND(AV9-AP9,0)) | BF9: =IF($B9="","",ROUND(AT9-AZ9,0)) | BG9: =IF($B9="","",ROUND(BF9*TarifPPh,0)) | BH9: =IF($B9="","",IF($D9="","Kategori kosong",IF($F9="","Tgl perolehan kosong",IF(N($H9)>$G9,"Residu > harga perolehan",IF(AND(LEFT($U9,8)="Bangunan",$W9="Saldo Menurun"),"Bangunan wajib Garis Lurus (Ps.11 UU PPh)",IF(AND($S9="Unit Produksi",N($K9)=0),"Isi kapasitas unit",IF(AND(OR($S9="Garis Lurus",$S9="Saldo Menurun"),N($T9)<=0),"Umur komersial kosong",IF(AND(OR($W9="Garis Lurus",$W9="Saldo Menurun"),N($V9)<=0),"Masa manfaat fiskal kosong",IF(AND($Q9<>"",$Q9<$F9),"Tgl pelepasan < perolehan","OK")))))))))
A10: =IF($B10="","",ROW()-6) | S10: =IF($B10="","",IF($I10<>"",$I10,IFERROR(INDEX(Kat_Metode,MATCH($D10,Kat_Nama,0)),""))) | T10: =IF($B10="","",IF($J10<>"",$J10,IFERROR(INDEX(Kat_Umur,MATCH($D10,Kat_Nama,0)),0))) | U10: =IF($B10="","",IF($N10<>"",$N10,IFERROR(INDEX(Kat_Kelompok,MATCH($D10,Kat_Nama,0)),""))) | V10: =IF($B10="","",IF($U10="Masa Manfaat Sebenarnya",N($O10),IFERROR(INDEX(Kel_Masa,MATCH($U10,Kel_Nama,0)),0))) | W10: =IF($B10="","",IF($P10<>"",$P10,IF(OR($U10="Tidak Disusutkan",$V10=0),"Tidak Disusutkan","Garis Lurus"))) | X10: =IF($B10="","",IF($Y10>TahunBuku*12+12,"Belum Diperoleh",IF($Z10<=TahunBuku*12,"Dilepas (thn lalu)",IF($AC10=1,"Dilepas thn ini",IF($AB10=1,"Perolehan baru","Aktif"))))) | Y10: =IF($B10="","",YEAR($F10)*12+MONTH($F10)) | Z10: =IF($B10="","",IF($Q10="",99999,YEAR($Q10)*12+MONTH($Q10))) | AA10: =IF($B10="","",--AND($Y10<=TahunBuku*12,$Z10>TahunBuku*12)) | AB10: =IF($B10="","",--AND($Y10>TahunBuku*12,$Y10<=TahunBuku*12+12)) | AC10: =IF($B10="","",--AND($Z10>TahunBuku*12,$Z10<=TahunBuku*12+12,$Y10<=$Z10)) | AD10: =IF($B10="","",IFERROR(IF($S10="Garis Lurus",$G10-($G10-$H10)*MIN($T10*12,MAX(0,TahunBuku*12-$Y10+1))/($T10*12),IF($S10="Saldo Menurun",IF(TahunBuku-1<YEAR($F10),$G10,IF(TahunBuku-1>=INT(($Y10+$T10*12-2)/12),$H10,MAX($H10,$G10*(1-2/$T10*(13-MONTH($F10))/12)*(1-2/$T10)^(TahunBuku-1-YEAR($F10))))),IF($S10="Unit Produksi",$G10-($G10-$H10)*MIN(1,N($L10)/$K10),$G10))),$G10)) | AE10: =IF($B10="","",IFERROR(IF($S10="Garis Lurus",$G10-($G10-$H10)*MIN($T10*12,MAX(0,TahunBuku*12+12-$Y10+1))/($T10*12),IF($S10="Saldo Menurun",IF(TahunBuku<YEAR($F10),$G10,IF(TahunBuku>=INT(($Y10+$T10*12-2)/12),$H10,MAX($H10,$G10*(1-2/$T10*(13-MONTH($F10))/12)*(1-2/$T10)^(TahunBuku-YEAR($F10))))),IF($S10="Unit Produksi",$G10-($G10-$H10)*MIN(1,(N($L10)+N($M10))/$K10),$G10))),$G10)) | AF10: =IF($B10="","",IF(OR($S10="Garis Lurus",$S10="Saldo Menurun",$S10="Unit Produksi"),MAX(0,IF($S10="Unit Produksi",TahunBuku*12+12,MIN(TahunBuku*12+12,$Y10+$T10*12-1))-MAX(TahunBuku*12+1,$Y10)+1),0)) | AG10: =IF($B10="","",IF(OR($S10="Garis Lurus",$S10="Saldo Menurun",$S10="Unit Produksi"),MAX(0,MIN($Z10,IF($S10="Unit Produksi",TahunBuku*12+12,MIN(TahunBuku*12+12,$Y10+$T10*12-1)))-MAX(TahunBuku*12+1,$Y10)+1),0)) | AH10: =IF($B10="","",IFERROR(IF($W10="Garis Lurus",$G10*(1-MIN($V10*12,MAX(0,TahunBuku*12-$Y10+1))/($V10*12)),IF($W10="Saldo Menurun",IF(TahunBuku-1<YEAR($F10),$G10,IF(TahunBuku-1>=INT(($Y10+$V10*12-2)/12),0,$G10*(1-2/$V10*(13-MONTH($F10))/12)*(1-2/$V10)^(TahunBuku-1-YEAR($F10)))),$G10)),$G10)) | AI10: =IF($B10="","",IFERROR(IF($W10="Garis Lurus",$G10*(1-MIN($V10*12,MAX(0,TahunBuku*12+12-$Y10+1))/($V10*12)),IF($W10="Saldo Menurun",IF(TahunBuku<YEAR($F10),$G10,IF(TahunBuku>=INT(($Y10+$V10*12-2)/12),0,$G10*(1-2/$V10*(13-MONTH($F10))/12)*(1-2/$V10)^(TahunBuku-YEAR($F10)))),$G10)),$G10)) | AJ10: =IF($B10="","",IF(OR($W10="Garis Lurus",$W10="Saldo Menurun"),MAX(0,MIN(TahunBuku*12+12,$Y10+$V10*12-1)-MAX(TahunBuku*12+1,$Y10)+1),0)) | AK10: =IF($B10="","",IF(OR($W10="Garis Lurus",$W10="Saldo Menurun"),MAX(0,MIN($Z10,TahunBuku*12+12,$Y10+$V10*12-1)-MAX(TahunBuku*12+1,$Y10)+1),0)) | AL10: =IF($B10="","",$G10*$AA10) | AM10: =IF($B10="","",$G10*$AB10) | AN10: =IF($B10="","",$G10*$AC10) | AO10: =IF($B10="","",AL10+AM10-AN10) | AP10: =IF($B10="","",($G10-$AD10)*$AA10) | AQ10: =IF($B10="","",IF($AF10=0,0,($AD10-$AE10)*$AG10/$AF10)*MAX($AA10,$AB10)) | AR10: =IF($B10="","",(AP10+AQ10)*$AC10) | AS10: =IF($B10="","",AP10+AQ10-AR10) | AT10: =IF($B10="","",AO10-AS10) | AU10: =IF($B10="","",IF($AC10=1,N($R10)-($G10-AR10),0)) | AV10: =IF($B10="","",($G10-$AH10)*$AA10) | AW10: =IF($B10="","",IF($AJ10=0,0,($AH10-$AI10)*$AK10/$AJ10)*MAX($AA10,$AB10)) | AX10: =IF($B10="","",(AV10+AW10)*$AC10) | AY10: =IF($B10="","",AV10+AW10-AX10) | AZ10: =IF($B10="","",AO10-AY10) | BA10: =IF($B10="","",IF($AC10=1,N($R10)-($G10-AX10),0)) | BB10: =IF($B10="","",ROUND(AQ10-AW10,0)) | BC10: =IF($B10="","",ROUND(BA10-AU10,0)) | BD10: =IF($B10="","",BB10+BC10) | BE10: =IF($B10="","",ROUND(AV10-AP10,0)) | BF10: =IF($B10="","",ROUND(AT10-AZ10,0)) | BG10: =IF($B10="","",ROUND(BF10*TarifPPh,0)) | BH10: =IF($B10="","",IF($D10="","Kategori kosong",IF($F10="","Tgl perolehan kosong",IF(N($H10)>$G10,"Residu > harga perolehan",IF(AND(LEFT($U10,8)="Bangunan",$W10="Saldo Menurun"),"Bangunan wajib Garis Lurus (Ps.11 UU PPh)",IF(AND($S10="Unit Produksi",N($K10)=0),"Isi kapasitas unit",IF(AND(OR($S10="Garis Lurus",$S10="Saldo Menurun"),N($T10)<=0),"Umur komersial kosong",IF(AND(OR($W10="Garis Lurus",$W10="Saldo Menurun"),N($V10)<=0),"Masa manfaat fiskal kosong",IF(AND($Q10<>"",$Q10<$F10),"Tgl pelepasan < perolehan","OK")))))))))
A11: =IF($B11="","",ROW()-6) | S11: =IF($B11="","",IF($I11<>"",$I11,IFERROR(INDEX(Kat_Metode,MATCH($D11,Kat_Nama,0)),""))) | T11: =IF($B11="","",IF($J11<>"",$J11,IFERROR(INDEX(Kat_Umur,MATCH($D11,Kat_Nama,0)),0))) | U11: =IF($B11="","",IF($N11<>"",$N11,IFERROR(INDEX(Kat_Kelompok,MATCH($D11,Kat_Nama,0)),""))) | V11: =IF($B11="","",IF($U11="Masa Manfaat Sebenarnya",N($O11),IFERROR(INDEX(Kel_Masa,MATCH($U11,Kel_Nama,0)),0))) | W11: =IF($B11="","",IF($P11<>"",$P11,IF(OR($U11="Tidak Disusutkan",$V11=0),"Tidak Disusutkan","Garis Lurus"))) | X11: =IF($B11="","",IF($Y11>TahunBuku*12+12,"Belum Diperoleh",IF($Z11<=TahunBuku*12,"Dilepas (thn lalu)",IF($AC11=1,"Dilepas thn ini",IF($AB11=1,"Perolehan baru","Aktif"))))) | Y11: =IF($B11="","",YEAR($F11)*12+MONTH($F11)) | Z11: =IF($B11="","",IF($Q11="",99999,YEAR($Q11)*12+MONTH($Q11))) | AA11: =IF($B11="","",--AND($Y11<=TahunBuku*12,$Z11>TahunBuku*12)) | AB11: =IF($B11="","",--AND($Y11>TahunBuku*12,$Y11<=TahunBuku*12+12)) | AC11: =IF($B11="","",--AND($Z11>TahunBuku*12,$Z11<=TahunBuku*12+12,$Y11<=$Z11)) | AD11: =IF($B11="","",IFERROR(IF($S11="Garis Lurus",$G11-($G11-$H11)*MIN($T11*12,MAX(0,TahunBuku*12-$Y11+1))/($T11*12),IF($S11="Saldo Menurun",IF(TahunBuku-1<YEAR($F11),$G11,IF(TahunBuku-1>=INT(($Y11+$T11*12-2)/12),$H11,MAX($H11,$G11*(1-2/$T11*(13-MONTH($F11))/12)*(1-2/$T11)^(TahunBuku-1-YEAR($F11))))),IF($S11="Unit Produksi",$G11-($G11-$H11)*MIN(1,N($L11)/$K11),$G11))),$G11)) | AE11: =IF($B11="","",IFERROR(IF($S11="Garis Lurus",$G11-($G11-$H11)*MIN($T11*12,MAX(0,TahunBuku*12+12-$Y11+1))/($T11*12),IF($S11="Saldo Menurun",IF(TahunBuku<YEAR($F11),$G11,IF(TahunBuku>=INT(($Y11+$T11*12-2)/12),$H11,MAX($H11,$G11*(1-2/$T11*(13-MONTH($F11))/12)*(1-2/$T11)^(TahunBuku-YEAR($F11))))),IF($S11="Unit Produksi",$G11-($G11-$H11)*MIN(1,(N($L11)+N($M11))/$K11),$G11))),$G11)) | AF11: =IF($B11="","",IF(OR($S11="Garis Lurus",$S11="Saldo Menurun",$S11="Unit Produksi"),MAX(0,IF($S11="Unit Produksi",TahunBuku*12+12,MIN(TahunBuku*12+12,$Y11+$T11*12-1))-MAX(TahunBuku*12+1,$Y11)+1),0)) | AG11: =IF($B11="","",IF(OR($S11="Garis Lurus",$S11="Saldo Menurun",$S11="Unit Produksi"),MAX(0,MIN($Z11,IF($S11="Unit Produksi",TahunBuku*12+12,MIN(TahunBuku*12+12,$Y11+$T11*12-1)))-MAX(TahunBuku*12+1,$Y11)+1),0)) | AH11: =IF($B11="","",IFERROR(IF($W11="Garis Lurus",$G11*(1-MIN($V11*12,MAX(0,TahunBuku*12-$Y11+1))/($V11*12)),IF($W11="Saldo Menurun",IF(TahunBuku-1<YEAR($F11),$G11,IF(TahunBuku-1>=INT(($Y11+$V11*12-2)/12),0,$G11*(1-2/$V11*(13-MONTH($F11))/12)*(1-2/$V11)^(TahunBuku-1-YEAR($F11)))),$G11)),$G11)) | AI11: =IF($B11="","",IFERROR(IF($W11="Garis Lurus",$G11*(1-MIN($V11*12,MAX(0,TahunBuku*12+12-$Y11+1))/($V11*12)),IF($W11="Saldo Menurun",IF(TahunBuku<YEAR($F11),$G11,IF(TahunBuku>=INT(($Y11+$V11*12-2)/12),0,$G11*(1-2/$V11*(13-MONTH($F11))/12)*(1-2/$V11)^(TahunBuku-YEAR($F11)))),$G11)),$G11)) | AJ11: =IF($B11="","",IF(OR($W11="Garis Lurus",$W11="Saldo Menurun"),MAX(0,MIN(TahunBuku*12+12,$Y11+$V11*12-1)-MAX(TahunBuku*12+1,$Y11)+1),0)) | AK11: =IF($B11="","",IF(OR($W11="Garis Lurus",$W11="Saldo Menurun"),MAX(0,MIN($Z11,TahunBuku*12+12,$Y11+$V11*12-1)-MAX(TahunBuku*12+1,$Y11)+1),0)) | AL11: =IF($B11="","",$G11*$AA11) | AM11: =IF($B11="","",$G11*$AB11) | AN11: =IF($B11="","",$G11*$AC11) | AO11: =IF($B11="","",AL11+AM11-AN11) | AP11: =IF($B11="","",($G11-$AD11)*$AA11) | AQ11: =IF($B11="","",IF($AF11=0,0,($AD11-$AE11)*$AG11/$AF11)*MAX($AA11,$AB11)) | AR11: =IF($B11="","",(AP11+AQ11)*$AC11) | AS11: =IF($B11="","",AP11+AQ11-AR11) | AT11: =IF($B11="","",AO11-AS11) | AU11: =IF($B11="","",IF($AC11=1,N($R11)-($G11-AR11),0)) | AV11: =IF($B11="","",($G11-$AH11)*$AA11) | AW11: =IF($B11="","",IF($AJ11=0,0,($AH11-$AI11)*$AK11/$AJ11)*MAX($AA11,$AB11)) | AX11: =IF($B11="","",(AV11+AW11)*$AC11) | AY11: =IF($B11="","",AV11+AW11-AX11) | AZ11: =IF($B11="","",AO11-AY11) | BA11: =IF($B11="","",IF($AC11=1,N($R11)-($G11-AX11),0)) | BB11: =IF($B11="","",ROUND(AQ11-AW11,0)) | BC11: =IF($B11="","",ROUND(BA11-AU11,0)) | BD11: =IF($B11="","",BB11+BC11) | BE11: =IF($B11="","",ROUND(AV11-AP11,0)) | BF11: =IF($B11="","",ROUND(AT11-AZ11,0)) | BG11: =IF($B11="","",ROUND(BF11*TarifPPh,0)) | BH11: =IF($B11="","",IF($D11="","Kategori kosong",IF($F11="","Tgl perolehan kosong",IF(N($H11)>$G11,"Residu > harga perolehan",IF(AND(LEFT($U11,8)="Bangunan",$W11="Saldo Menurun"),"Bangunan wajib Garis Lurus (Ps.11 UU PPh)",IF(AND($S11="Unit Produksi",N($K11)=0),"Isi kapasitas unit",IF(AND(OR($S11="Garis Lurus",$S11="Saldo Menurun"),N($T11)<=0),"Umur komersial kosong",IF(AND(OR($W11="Garis Lurus",$W11="Saldo Menurun"),N($V11)<=0),"Masa manfaat fiskal kosong",IF(AND($Q11<>"",$Q11<$F11),"Tgl pelepasan < perolehan","OK")))))))))
A12: =IF($B12="","",ROW()-6) | S12: =IF($B12="","",IF($I12<>"",$I12,IFERROR(INDEX(Kat_Metode,MATCH($D12,Kat_Nama,0)),""))) | T12: =IF($B12="","",IF($J12<>"",$J12,IFERROR(INDEX(Kat_Umur,MATCH($D12,Kat_Nama,0)),0))) | U12: =IF($B12="","",IF($N12<>"",$N12,IFERROR(INDEX(Kat_Kelompok,MATCH($D12,Kat_Nama,0)),""))) | V12: =IF($B12="","",IF($U12="Masa Manfaat Sebenarnya",N($O12),IFERROR(INDEX(Kel_Masa,MATCH($U12,Kel_Nama,0)),0))) | W12: =IF($B12="","",IF($P12<>"",$P12,IF(OR($U12="Tidak Disusutkan",$V12=0),"Tidak Disusutkan","Garis Lurus"))) | X12: =IF($B12="","",IF($Y12>TahunBuku*12+12,"Belum Diperoleh",IF($Z12<=TahunBuku*12,"Dilepas (thn lalu)",IF($AC12=1,"Dilepas thn ini",IF($AB12=1,"Perolehan baru","Aktif"))))) | Y12: =IF($B12="","",YEAR($F12)*12+MONTH($F12)) | Z12: =IF($B12="","",IF($Q12="",99999,YEAR($Q12)*12+MONTH($Q12))) | AA12: =IF($B12="","",--AND($Y12<=TahunBuku*12,$Z12>TahunBuku*12)) | AB12: =IF($B12="","",--AND($Y12>TahunBuku*12,$Y12<=TahunBuku*12+12)) | AC12: =IF($B12="","",--AND($Z12>TahunBuku*12,$Z12<=TahunBuku*12+12,$Y12<=$Z12)) | AD12: =IF($B12="","",IFERROR(IF($S12="Garis Lurus",$G12-($G12-$H12)*MIN($T12*12,MAX(0,TahunBuku*12-$Y12+1))/($T12*12),IF($S12="Saldo Menurun",IF(TahunBuku-1<YEAR($F12),$G12,IF(TahunBuku-1>=INT(($Y12+$T12*12-2)/12),$H12,MAX($H12,$G12*(1-2/$T12*(13-MONTH($F12))/12)*(1-2/$T12)^(TahunBuku-1-YEAR($F12))))),IF($S12="Unit Produksi",$G12-($G12-$H12)*MIN(1,N($L12)/$K12),$G12))),$G12)) | AE12: =IF($B12="","",IFERROR(IF($S12="Garis Lurus",$G12-($G12-$H12)*MIN($T12*12,MAX(0,TahunBuku*12+12-$Y12+1))/($T12*12),IF($S12="Saldo Menurun",IF(TahunBuku<YEAR($F12),$G12,IF(TahunBuku>=INT(($Y12+$T12*12-2)/12),$H12,MAX($H12,$G12*(1-2/$T12*(13-MONTH($F12))/12)*(1-2/$T12)^(TahunBuku-YEAR($F12))))),IF($S12="Unit Produksi",$G12-($G12-$H12)*MIN(1,(N($L12)+N($M12))/$K12),$G12))),$G12)) | AF12: =IF($B12="","",IF(OR($S12="Garis Lurus",$S12="Saldo Menurun",$S12="Unit Produksi"),MAX(0,IF($S12="Unit Produksi",TahunBuku*12+12,MIN(TahunBuku*12+12,$Y12+$T12*12-1))-MAX(TahunBuku*12+1,$Y12)+1),0)) | AG12: =IF($B12="","",IF(OR($S12="Garis Lurus",$S12="Saldo Menurun",$S12="Unit Produksi"),MAX(0,MIN($Z12,IF($S12="Unit Produksi",TahunBuku*12+12,MIN(TahunBuku*12+12,$Y12+$T12*12-1)))-MAX(TahunBuku*12+1,$Y12)+1),0)) | AH12: =IF($B12="","",IFERROR(IF($W12="Garis Lurus",$G12*(1-MIN($V12*12,MAX(0,TahunBuku*12-$Y12+1))/($V12*12)),IF($W12="Saldo Menurun",IF(TahunBuku-1<YEAR($F12),$G12,IF(TahunBuku-1>=INT(($Y12+$V12*12-2)/12),0,$G12*(1-2/$V12*(13-MONTH($F12))/12)*(1-2/$V12)^(TahunBuku-1-YEAR($F12)))),$G12)),$G12)) | AI12: =IF($B12="","",IFERROR(IF($W12="Garis Lurus",$G12*(1-MIN($V12*12,MAX(0,TahunBuku*12+12-$Y12+1))/($V12*12)),IF($W12="Saldo Menurun",IF(TahunBuku<YEAR($F12),$G12,IF(TahunBuku>=INT(($Y12+$V12*12-2)/12),0,$G12*(1-2/$V12*(13-MONTH($F12))/12)*(1-2/$V12)^(TahunBuku-YEAR($F12)))),$G12)),$G12)) | AJ12: =IF($B12="","",IF(OR($W12="Garis Lurus",$W12="Saldo Menurun"),MAX(0,MIN(TahunBuku*12+12,$Y12+$V12*12-1)-MAX(TahunBuku*12+1,$Y12)+1),0)) | AK12: =IF($B12="","",IF(OR($W12="Garis Lurus",$W12="Saldo Menurun"),MAX(0,MIN($Z12,TahunBuku*12+12,$Y12+$V12*12-1)-MAX(TahunBuku*12+1,$Y12)+1),0)) | AL12: =IF($B12="","",$G12*$AA12) | AM12: =IF($B12="","",$G12*$AB12) | AN12: =IF($B12="","",$G12*$AC12) | AO12: =IF($B12="","",AL12+AM12-AN12) | AP12: =IF($B12="","",($G12-$AD12)*$AA12) | AQ12: =IF($B12="","",IF($AF12=0,0,($AD12-$AE12)*$AG12/$AF12)*MAX($AA12,$AB12)) | AR12: =IF($B12="","",(AP12+AQ12)*$AC12) | AS12: =IF($B12="","",AP12+AQ12-AR12) | AT12: =IF($B12="","",AO12-AS12) | AU12: =IF($B12="","",IF($AC12=1,N($R12)-($G12-AR12),0)) | AV12: =IF($B12="","",($G12-$AH12)*$AA12) | AW12: =IF($B12="","",IF($AJ12=0,0,($AH12-$AI12)*$AK12/$AJ12)*MAX($AA12,$AB12)) | AX12: =IF($B12="","",(AV12+AW12)*$AC12) | AY12: =IF($B12="","",AV12+AW12-AX12) | AZ12: =IF($B12="","",AO12-AY12) | BA12: =IF($B12="","",IF($AC12=1,N($R12)-($G12-AX12),0)) | BB12: =IF($B12="","",ROUND(AQ12-AW12,0)) | BC12: =IF($B12="","",ROUND(BA12-AU12,0)) | BD12: =IF($B12="","",BB12+BC12) | BE12: =IF($B12="","",ROUND(AV12-AP12,0)) | BF12: =IF($B12="","",ROUND(AT12-AZ12,0)) | BG12: =IF($B12="","",ROUND(BF12*TarifPPh,0)) | BH12: =IF($B12="","",IF($D12="","Kategori kosong",IF($F12="","Tgl perolehan kosong",IF(N($H12)>$G12,"Residu > harga perolehan",IF(AND(LEFT($U12,8)="Bangunan",$W12="Saldo Menurun"),"Bangunan wajib Garis Lurus (Ps.11 UU PPh)",IF(AND($S12="Unit Produksi",N($K12)=0),"Isi kapasitas unit",IF(AND(OR($S12="Garis Lurus",$S12="Saldo Menurun"),N($T12)<=0),"Umur komersial kosong",IF(AND(OR($W12="Garis Lurus",$W12="Saldo Menurun"),N($V12)<=0),"Masa manfaat fiskal kosong",IF(AND($Q12<>"",$Q12<$F12),"Tgl pelepasan < perolehan","OK")))))))))
A13: =IF($B13="","",ROW()-6) | S13: =IF($B13="","",IF($I13<>"",$I13,IFERROR(INDEX(Kat_Metode,MATCH($D13,Kat_Nama,0)),""))) | T13: =IF($B13="","",IF($J13<>"",$J13,IFERROR(INDEX(Kat_Umur,MATCH($D13,Kat_Nama,0)),0))) | U13: =IF($B13="","",IF($N13<>"",$N13,IFERROR(INDEX(Kat_Kelompok,MATCH($D13,Kat_Nama,0)),""))) | V13: =IF($B13="","",IF($U13="Masa Manfaat Sebenarnya",N($O13),IFERROR(INDEX(Kel_Masa,MATCH($U13,Kel_Nama,0)),0))) | W13: =IF($B13="","",IF($P13<>"",$P13,IF(OR($U13="Tidak Disusutkan",$V13=0),"Tidak Disusutkan","Garis Lurus"))) | X13: =IF($B13="","",IF($Y13>TahunBuku*12+12,"Belum Diperoleh",IF($Z13<=TahunBuku*12,"Dilepas (thn lalu)",IF($AC13=1,"Dilepas thn ini",IF($AB13=1,"Perolehan baru","Aktif"))))) | Y13: =IF($B13="","",YEAR($F13)*12+MONTH($F13)) | Z13: =IF($B13="","",IF($Q13="",99999,YEAR($Q13)*12+MONTH($Q13))) | AA13: =IF($B13="","",--AND($Y13<=TahunBuku*12,$Z13>TahunBuku*12)) | AB13: =IF($B13="","",--AND($Y13>TahunBuku*12,$Y13<=TahunBuku*12+12)) | AC13: =IF($B13="","",--AND($Z13>TahunBuku*12,$Z13<=TahunBuku*12+12,$Y13<=$Z13)) | AD13: =IF($B13="","",IFERROR(IF($S13="Garis Lurus",$G13-($G13-$H13)*MIN($T13*12,MAX(0,TahunBuku*12-$Y13+1))/($T13*12),IF($S13="Saldo Menurun",IF(TahunBuku-1<YEAR($F13),$G13,IF(TahunBuku-1>=INT(($Y13+$T13*12-2)/12),$H13,MAX($H13,$G13*(1-2/$T13*(13-MONTH($F13))/12)*(1-2/$T13)^(TahunBuku-1-YEAR($F13))))),IF($S13="Unit Produksi",$G13-($G13-$H13)*MIN(1,N($L13)/$K13),$G13))),$G13)) | AE13: =IF($B13="","",IFERROR(IF($S13="Garis Lurus",$G13-($G13-$H13)*MIN($T13*12,MAX(0,TahunBuku*12+12-$Y13+1))/($T13*12),IF($S13="Saldo Menurun",IF(TahunBuku<YEAR($F13),$G13,IF(TahunBuku>=INT(($Y13+$T13*12-2)/12),$H13,MAX($H13,$G13*(1-2/$T13*(13-MONTH($F13))/12)*(1-2/$T13)^(TahunBuku-YEAR($F13))))),IF($S13="Unit Produksi",$G13-($G13-$H13)*MIN(1,(N($L13)+N($M13))/$K13),$G13))),$G13)) | AF13: =IF($B13="","",IF(OR($S13="Garis Lurus",$S13="Saldo Menurun",$S13="Unit Produksi"),MAX(0,IF($S13="Unit Produksi",TahunBuku*12+12,MIN(TahunBuku*12+12,$Y13+$T13*12-1))-MAX(TahunBuku*12+1,$Y13)+1),0)) | AG13: =IF($B13="","",IF(OR($S13="Garis Lurus",$S13="Saldo Menurun",$S13="Unit Produksi"),MAX(0,MIN($Z13,IF($S13="Unit Produksi",TahunBuku*12+12,MIN(TahunBuku*12+12,$Y13+$T13*12-1)))-MAX(TahunBuku*12+1,$Y13)+1),0)) | AH13: =IF($B13="","",IFERROR(IF($W13="Garis Lurus",$G13*(1-MIN($V13*12,MAX(0,TahunBuku*12-$Y13+1))/($V13*12)),IF($W13="Saldo Menurun",IF(TahunBuku-1<YEAR($F13),$G13,IF(TahunBuku-1>=INT(($Y13+$V13*12-2)/12),0,$G13*(1-2/$V13*(13-MONTH($F13))/12)*(1-2/$V13)^(TahunBuku-1-YEAR($F13)))),$G13)),$G13)) | AI13: =IF($B13="","",IFERROR(IF($W13="Garis Lurus",$G13*(1-MIN($V13*12,MAX(0,TahunBuku*12+12-$Y13+1))/($V13*12)),IF($W13="Saldo Menurun",IF(TahunBuku<YEAR($F13),$G13,IF(TahunBuku>=INT(($Y13+$V13*12-2)/12),0,$G13*(1-2/$V13*(13-MONTH($F13))/12)*(1-2/$V13)^(TahunBuku-YEAR($F13)))),$G13)),$G13)) | AJ13: =IF($B13="","",IF(OR($W13="Garis Lurus",$W13="Saldo Menurun"),MAX(0,MIN(TahunBuku*12+12,$Y13+$V13*12-1)-MAX(TahunBuku*12+1,$Y13)+1),0)) | AK13: =IF($B13="","",IF(OR($W13="Garis Lurus",$W13="Saldo Menurun"),MAX(0,MIN($Z13,TahunBuku*12+12,$Y13+$V13*12-1)-MAX(TahunBuku*12+1,$Y13)+1),0)) | AL13: =IF($B13="","",$G13*$AA13) | AM13: =IF($B13="","",$G13*$AB13) | AN13: =IF($B13="","",$G13*$AC13) | AO13: =IF($B13="","",AL13+AM13-AN13) | AP13: =IF($B13="","",($G13-$AD13)*$AA13) | AQ13: =IF($B13="","",IF($AF13=0,0,($AD13-$AE13)*$AG13/$AF13)*MAX($AA13,$AB13)) | AR13: =IF($B13="","",(AP13+AQ13)*$AC13) | AS13: =IF($B13="","",AP13+AQ13-AR13) | AT13: =IF($B13="","",AO13-AS13) | AU13: =IF($B13="","",IF($AC13=1,N($R13)-($G13-AR13),0)) | AV13: =IF($B13="","",($G13-$AH13)*$AA13) | AW13: =IF($B13="","",IF($AJ13=0,0,($AH13-$AI13)*$AK13/$AJ13)*MAX($AA13,$AB13)) | AX13: =IF($B13="","",(AV13+AW13)*$AC13) | AY13: =IF($B13="","",AV13+AW13-AX13) | AZ13: =IF($B13="","",AO13-AY13) | BA13: =IF($B13="","",IF($AC13=1,N($R13)-($G13-AX13),0)) | BB13: =IF($B13="","",ROUND(AQ13-AW13,0)) | BC13: =IF($B13="","",ROUND(BA13-AU13,0)) | BD13: =IF($B13="","",BB13+BC13) | BE13: =IF($B13="","",ROUND(AV13-AP13,0)) | BF13: =IF($B13="","",ROUND(AT13-AZ13,0)) | BG13: =IF($B13="","",ROUND(BF13*TarifPPh,0)) | BH13: =IF($B13="","",IF($D13="","Kategori kosong",IF($F13="","Tgl perolehan kosong",IF(N($H13)>$G13,"Residu > harga perolehan",IF(AND(LEFT($U13,8)="Bangunan",$W13="Saldo Menurun"),"Bangunan wajib Garis Lurus (Ps.11 UU PPh)",IF(AND($S13="Unit Produksi",N($K13)=0),"Isi kapasitas unit",IF(AND(OR($S13="Garis Lurus",$S13="Saldo Menurun"),N($T13)<=0),"Umur komersial kosong",IF(AND(OR($W13="Garis Lurus",$W13="Saldo Menurun"),N($V13)<=0),"Masa manfaat fiskal kosong",IF(AND($Q13<>"",$Q13<$F13),"Tgl pelepasan < perolehan","OK")))))))))
A14: =IF($B14="","",ROW()-6) | S14: =IF($B14="","",IF($I14<>"",$I14,IFERROR(INDEX(Kat_Metode,MATCH($D14,Kat_Nama,0)),""))) | T14: =IF($B14="","",IF($J14<>"",$J14,IFERROR(INDEX(Kat_Umur,MATCH($D14,Kat_Nama,0)),0))) | U14: =IF($B14="","",IF($N14<>"",$N14,IFERROR(INDEX(Kat_Kelompok,MATCH($D14,Kat_Nama,0)),""))) | V14: =IF($B14="","",IF($U14="Masa Manfaat Sebenarnya",N($O14),IFERROR(INDEX(Kel_Masa,MATCH($U14,Kel_Nama,0)),0))) | W14: =IF($B14="","",IF($P14<>"",$P14,IF(OR($U14="Tidak Disusutkan",$V14=0),"Tidak Disusutkan","Garis Lurus"))) | X14: =IF($B14="","",IF($Y14>TahunBuku*12+12,"Belum Diperoleh",IF($Z14<=TahunBuku*12,"Dilepas (thn lalu)",IF($AC14=1,"Dilepas thn ini",IF($AB14=1,"Perolehan baru","Aktif"))))) | Y14: =IF($B14="","",YEAR($F14)*12+MONTH($F14)) | Z14: =IF($B14="","",IF($Q14="",99999,YEAR($Q14)*12+MONTH($Q14))) | AA14: =IF($B14="","",--AND($Y14<=TahunBuku*12,$Z14>TahunBuku*12)) | AB14: =IF($B14="","",--AND($Y14>TahunBuku*12,$Y14<=TahunBuku*12+12)) | AC14: =IF($B14="","",--AND($Z14>TahunBuku*12,$Z14<=TahunBuku*12+12,$Y14<=$Z14)) | AD14: =IF($B14="","",IFERROR(IF($S14="Garis Lurus",$G14-($G14-$H14)*MIN($T14*12,MAX(0,TahunBuku*12-$Y14+1))/($T14*12),IF($S14="Saldo Menurun",IF(TahunBuku-1<YEAR($F14),$G14,IF(TahunBuku-1>=INT(($Y14+$T14*12-2)/12),$H14,MAX($H14,$G14*(1-2/$T14*(13-MONTH($F14))/12)*(1-2/$T14)^(TahunBuku-1-YEAR($F14))))),IF($S14="Unit Produksi",$G14-($G14-$H14)*MIN(1,N($L14)/$K14),$G14))),$G14)) | AE14: =IF($B14="","",IFERROR(IF($S14="Garis Lurus",$G14-($G14-$H14)*MIN($T14*12,MAX(0,TahunBuku*12+12-$Y14+1))/($T14*12),IF($S14="Saldo Menurun",IF(TahunBuku<YEAR($F14),$G14,IF(TahunBuku>=INT(($Y14+$T14*12-2)/12),$H14,MAX($H14,$G14*(1-2/$T14*(13-MONTH($F14))/12)*(1-2/$T14)^(TahunBuku-YEAR($F14))))),IF($S14="Unit Produksi",$G14-($G14-$H14)*MIN(1,(N($L14)+N($M14))/$K14),$G14))),$G14)) | AF14: =IF($B14="","",IF(OR($S14="Garis Lurus",$S14="Saldo Menurun",$S14="Unit Produksi"),MAX(0,IF($S14="Unit Produksi",TahunBuku*12+12,MIN(TahunBuku*12+12,$Y14+$T14*12-1))-MAX(TahunBuku*12+1,$Y14)+1),0)) | AG14: =IF($B14="","",IF(OR($S14="Garis Lurus",$S14="Saldo Menurun",$S14="Unit Produksi"),MAX(0,MIN($Z14,IF($S14="Unit Produksi",TahunBuku*12+12,MIN(TahunBuku*12+12,$Y14+$T14*12-1)))-MAX(TahunBuku*12+1,$Y14)+1),0)) | AH14: =IF($B14="","",IFERROR(IF($W14="Garis Lurus",$G14*(1-MIN($V14*12,MAX(0,TahunBuku*12-$Y14+1))/($V14*12)),IF($W14="Saldo Menurun",IF(TahunBuku-1<YEAR($F14),$G14,IF(TahunBuku-1>=INT(($Y14+$V14*12-2)/12),0,$G14*(1-2/$V14*(13-MONTH($F14))/12)*(1-2/$V14)^(TahunBuku-1-YEAR($F14)))),$G14)),$G14)) | AI14: =IF($B14="","",IFERROR(IF($W14="Garis Lurus",$G14*(1-MIN($V14*12,MAX(0,TahunBuku*12+12-$Y14+1))/($V14*12)),IF($W14="Saldo Menurun",IF(TahunBuku<YEAR($F14),$G14,IF(TahunBuku>=INT(($Y14+$V14*12-2)/12),0,$G14*(1-2/$V14*(13-MONTH($F14))/12)*(1-2/$V14)^(TahunBuku-YEAR($F14)))),$G14)),$G14)) | AJ14: =IF($B14="","",IF(OR($W14="Garis Lurus",$W14="Saldo Menurun"),MAX(0,MIN(TahunBuku*12+12,$Y14+$V14*12-1)-MAX(TahunBuku*12+1,$Y14)+1),0)) | AK14: =IF($B14="","",IF(OR($W14="Garis Lurus",$W14="Saldo Menurun"),MAX(0,MIN($Z14,TahunBuku*12+12,$Y14+$V14*12-1)-MAX(TahunBuku*12+1,$Y14)+1),0)) | AL14: =IF($B14="","",$G14*$AA14) | AM14: =IF($B14="","",$G14*$AB14) | AN14: =IF($B14="","",$G14*$AC14) | AO14: =IF($B14="","",AL14+AM14-AN14) | AP14: =IF($B14="","",($G14-$AD14)*$AA14) | AQ14: =IF($B14="","",IF($AF14=0,0,($AD14-$AE14)*$AG14/$AF14)*MAX($AA14,$AB14)) | AR14: =IF($B14="","",(AP14+AQ14)*$AC14) | AS14: =IF($B14="","",AP14+AQ14-AR14) | AT14: =IF($B14="","",AO14-AS14) | AU14: =IF($B14="","",IF($AC14=1,N($R14)-($G14-AR14),0)) | AV14: =IF($B14="","",($G14-$AH14)*$AA14) | AW14: =IF($B14="","",IF($AJ14=0,0,($AH14-$AI14)*$AK14/$AJ14)*MAX($AA14,$AB14)) | AX14: =IF($B14="","",(AV14+AW14)*$AC14) | AY14: =IF($B14="","",AV14+AW14-AX14) | AZ14: =IF($B14="","",AO14-AY14) | BA14: =IF($B14="","",IF($AC14=1,N($R14)-($G14-AX14),0)) | BB14: =IF($B14="","",ROUND(AQ14-AW14,0)) | BC14: =IF($B14="","",ROUND(BA14-AU14,0)) | BD14: =IF($B14="","",BB14+BC14) | BE14: =IF($B14="","",ROUND(AV14-AP14,0)) | BF14: =IF($B14="","",ROUND(AT14-AZ14,0)) | BG14: =IF($B14="","",ROUND(BF14*TarifPPh,0)) | BH14: =IF($B14="","",IF($D14="","Kategori kosong",IF($F14="","Tgl perolehan kosong",IF(N($H14)>$G14,"Residu > harga perolehan",IF(AND(LEFT($U14,8)="Bangunan",$W14="Saldo Menurun"),"Bangunan wajib Garis Lurus (Ps.11 UU PPh)",IF(AND($S14="Unit Produksi",N($K14)=0),"Isi kapasitas unit",IF(AND(OR($S14="Garis Lurus",$S14="Saldo Menurun"),N($T14)<=0),"Umur komersial kosong",IF(AND(OR($W14="Garis Lurus",$W14="Saldo Menurun"),N($V14)<=0),"Masa manfaat fiskal kosong",IF(AND($Q14<>"",$Q14<$F14),"Tgl pelepasan < perolehan","OK")))))))))
A15: =IF($B15="","",ROW()-6) | S15: =IF($B15="","",IF($I15<>"",$I15,IFERROR(INDEX(Kat_Metode,MATCH($D15,Kat_Nama,0)),""))) | T15: =IF($B15="","",IF($J15<>"",$J15,IFERROR(INDEX(Kat_Umur,MATCH($D15,Kat_Nama,0)),0))) | U15: =IF($B15="","",IF($N15<>"",$N15,IFERROR(INDEX(Kat_Kelompok,MATCH($D15,Kat_Nama,0)),""))) | V15: =IF($B15="","",IF($U15="Masa Manfaat Sebenarnya",N($O15),IFERROR(INDEX(Kel_Masa,MATCH($U15,Kel_Nama,0)),0))) | W15: =IF($B15="","",IF($P15<>"",$P15,IF(OR($U15="Tidak Disusutkan",$V15=0),"Tidak Disusutkan","Garis Lurus"))) | X15: =IF($B15="","",IF($Y15>TahunBuku*12+12,"Belum Diperoleh",IF($Z15<=TahunBuku*12,"Dilepas (thn lalu)",IF($AC15=1,"Dilepas thn ini",IF($AB15=1,"Perolehan baru","Aktif"))))) | Y15: =IF($B15="","",YEAR($F15)*12+MONTH($F15)) | Z15: =IF($B15="","",IF($Q15="",99999,YEAR($Q15)*12+MONTH($Q15))) | AA15: =IF($B15="","",--AND($Y15<=TahunBuku*12,$Z15>TahunBuku*12)) | AB15: =IF($B15="","",--AND($Y15>TahunBuku*12,$Y15<=TahunBuku*12+12)) | AC15: =IF($B15="","",--AND($Z15>TahunBuku*12,$Z15<=TahunBuku*12+12,$Y15<=$Z15)) | AD15: =IF($B15="","",IFERROR(IF($S15="Garis Lurus",$G15-($G15-$H15)*MIN($T15*12,MAX(0,TahunBuku*12-$Y15+1))/($T15*12),IF($S15="Saldo Menurun",IF(TahunBuku-1<YEAR($F15),$G15,IF(TahunBuku-1>=INT(($Y15+$T15*12-2)/12),$H15,MAX($H15,$G15*(1-2/$T15*(13-MONTH($F15))/12)*(1-2/$T15)^(TahunBuku-1-YEAR($F15))))),IF($S15="Unit Produksi",$G15-($G15-$H15)*MIN(1,N($L15)/$K15),$G15))),$G15)) | AE15: =IF($B15="","",IFERROR(IF($S15="Garis Lurus",$G15-($G15-$H15)*MIN($T15*12,MAX(0,TahunBuku*12+12-$Y15+1))/($T15*12),IF($S15="Saldo Menurun",IF(TahunBuku<YEAR($F15),$G15,IF(TahunBuku>=INT(($Y15+$T15*12-2)/12),$H15,MAX($H15,$G15*(1-2/$T15*(13-MONTH($F15))/12)*(1-2/$T15)^(TahunBuku-YEAR($F15))))),IF($S15="Unit Produksi",$G15-($G15-$H15)*MIN(1,(N($L15)+N($M15))/$K15),$G15))),$G15)) | AF15: =IF($B15="","",IF(OR($S15="Garis Lurus",$S15="Saldo Menurun",$S15="Unit Produksi"),MAX(0,IF($S15="Unit Produksi",TahunBuku*12+12,MIN(TahunBuku*12+12,$Y15+$T15*12-1))-MAX(TahunBuku*12+1,$Y15)+1),0)) | AG15: =IF($B15="","",IF(OR($S15="Garis Lurus",$S15="Saldo Menurun",$S15="Unit Produksi"),MAX(0,MIN($Z15,IF($S15="Unit Produksi",TahunBuku*12+12,MIN(TahunBuku*12+12,$Y15+$T15*12-1)))-MAX(TahunBuku*12+1,$Y15)+1),0)) | AH15: =IF($B15="","",IFERROR(IF($W15="Garis Lurus",$G15*(1-MIN($V15*12,MAX(0,TahunBuku*12-$Y15+1))/($V15*12)),IF($W15="Saldo Menurun",IF(TahunBuku-1<YEAR($F15),$G15,IF(TahunBuku-1>=INT(($Y15+$V15*12-2)/12),0,$G15*(1-2/$V15*(13-MONTH($F15))/12)*(1-2/$V15)^(TahunBuku-1-YEAR($F15)))),$G15)),$G15)) | AI15: =IF($B15="","",IFERROR(IF($W15="Garis Lurus",$G15*(1-MIN($V15*12,MAX(0,TahunBuku*12+12-$Y15+1))/($V15*12)),IF($W15="Saldo Menurun",IF(TahunBuku<YEAR($F15),$G15,IF(TahunBuku>=INT(($Y15+$V15*12-2)/12),0,$G15*(1-2/$V15*(13-MONTH($F15))/12)*(1-2/$V15)^(TahunBuku-YEAR($F15)))),$G15)),$G15)) | AJ15: =IF($B15="","",IF(OR($W15="Garis Lurus",$W15="Saldo Menurun"),MAX(0,MIN(TahunBuku*12+12,$Y15+$V15*12-1)-MAX(TahunBuku*12+1,$Y15)+1),0)) | AK15: =IF($B15="","",IF(OR($W15="Garis Lurus",$W15="Saldo Menurun"),MAX(0,MIN($Z15,TahunBuku*12+12,$Y15+$V15*12-1)-MAX(TahunBuku*12+1,$Y15)+1),0)) | AL15: =IF($B15="","",$G15*$AA15) | AM15: =IF($B15="","",$G15*$AB15) | AN15: =IF($B15="","",$G15*$AC15) | AO15: =IF($B15="","",AL15+AM15-AN15) | AP15: =IF($B15="","",($G15-$AD15)*$AA15) | AQ15: =IF($B15="","",IF($AF15=0,0,($AD15-$AE15)*$AG15/$AF15)*MAX($AA15,$AB15)) | AR15: =IF($B15="","",(AP15+AQ15)*$AC15) | AS15: =IF($B15="","",AP15+AQ15-AR15) | AT15: =IF($B15="","",AO15-AS15) | AU15: =IF($B15="","",IF($AC15=1,N($R15)-($G15-AR15),0)) | AV15: =IF($B15="","",($G15-$AH15)*$AA15) | AW15: =IF($B15="","",IF($AJ15=0,0,($AH15-$AI15)*$AK15/$AJ15)*MAX($AA15,$AB15)) | AX15: =IF($B15="","",(AV15+AW15)*$AC15) | AY15: =IF($B15="","",AV15+AW15-AX15) | AZ15: =IF($B15="","",AO15-AY15) | BA15: =IF($B15="","",IF($AC15=1,N($R15)-($G15-AX15),0)) | BB15: =IF($B15="","",ROUND(AQ15-AW15,0)) | BC15: =IF($B15="","",ROUND(BA15-AU15,0)) | BD15: =IF($B15="","",BB15+BC15) | BE15: =IF($B15="","",ROUND(AV15-AP15,0)) | BF15: =IF($B15="","",ROUND(AT15-AZ15,0)) | BG15: =IF($B15="","",ROUND(BF15*TarifPPh,0)) | BH15: =IF($B15="","",IF($D15="","Kategori kosong",IF($F15="","Tgl perolehan kosong",IF(N($H15)>$G15,"Residu > harga perolehan",IF(AND(LEFT($U15,8)="Bangunan",$W15="Saldo Menurun"),"Bangunan wajib Garis Lurus (Ps.11 UU PPh)",IF(AND($S15="Unit Produksi",N($K15)=0),"Isi kapasitas unit",IF(AND(OR($S15="Garis Lurus",$S15="Saldo Menurun"),N($T15)<=0),"Umur komersial kosong",IF(AND(OR($W15="Garis Lurus",$W15="Saldo Menurun"),N($V15)<=0),"Masa manfaat fiskal kosong",IF(AND($Q15<>"",$Q15<$F15),"Tgl pelepasan < perolehan","OK")))))))))
A16: =IF($B16="","",ROW()-6) | S16: =IF($B16="","",IF($I16<>"",$I16,IFERROR(INDEX(Kat_Metode,MATCH($D16,Kat_Nama,0)),""))) | T16: =IF($B16="","",IF($J16<>"",$J16,IFERROR(INDEX(Kat_Umur,MATCH($D16,Kat_Nama,0)),0))) | U16: =IF($B16="","",IF($N16<>"",$N16,IFERROR(INDEX(Kat_Kelompok,MATCH($D16,Kat_Nama,0)),""))) | V16: =IF($B16="","",IF($U16="Masa Manfaat Sebenarnya",N($O16),IFERROR(INDEX(Kel_Masa,MATCH($U16,Kel_Nama,0)),0))) | W16: =IF($B16="","",IF($P16<>"",$P16,IF(OR($U16="Tidak Disusutkan",$V16=0),"Tidak Disusutkan","Garis Lurus"))) | X16: =IF($B16="","",IF($Y16>TahunBuku*12+12,"Belum Diperoleh",IF($Z16<=TahunBuku*12,"Dilepas (thn lalu)",IF($AC16=1,"Dilepas thn ini",IF($AB16=1,"Perolehan baru","Aktif"))))) | Y16: =IF($B16="","",YEAR($F16)*12+MONTH($F16)) | Z16: =IF($B16="","",IF($Q16="",99999,YEAR($Q16)*12+MONTH($Q16))) | AA16: =IF($B16="","",--AND($Y16<=TahunBuku*12,$Z16>TahunBuku*12)) | AB16: =IF($B16="","",--AND($Y16>TahunBuku*12,$Y16<=TahunBuku*12+12)) | AC16: =IF($B16="","",--AND($Z16>TahunBuku*12,$Z16<=TahunBuku*12+12,$Y16<=$Z16)) | AD16: =IF($B16="","",IFERROR(IF($S16="Garis Lurus",$G16-($G16-$H16)*MIN($T16*12,MAX(0,TahunBuku*12-$Y16+1))/($T16*12),IF($S16="Saldo Menurun",IF(TahunBuku-1<YEAR($F16),$G16,IF(TahunBuku-1>=INT(($Y16+$T16*12-2)/12),$H16,MAX($H16,$G16*(1-2/$T16*(13-MONTH($F16))/12)*(1-2/$T16)^(TahunBuku-1-YEAR($F16))))),IF($S16="Unit Produksi",$G16-($G16-$H16)*MIN(1,N($L16)/$K16),$G16))),$G16)) | AE16: =IF($B16="","",IFERROR(IF($S16="Garis Lurus",$G16-($G16-$H16)*MIN($T16*12,MAX(0,TahunBuku*12+12-$Y16+1))/($T16*12),IF($S16="Saldo Menurun",IF(TahunBuku<YEAR($F16),$G16,IF(TahunBuku>=INT(($Y16+$T16*12-2)/12),$H16,MAX($H16,$G16*(1-2/$T16*(13-MONTH($F16))/12)*(1-2/$T16)^(TahunBuku-YEAR($F16))))),IF($S16="Unit Produksi",$G16-($G16-$H16)*MIN(1,(N($L16)+N($M16))/$K16),$G16))),$G16)) | AF16: =IF($B16="","",IF(OR($S16="Garis Lurus",$S16="Saldo Menurun",$S16="Unit Produksi"),MAX(0,IF($S16="Unit Produksi",TahunBuku*12+12,MIN(TahunBuku*12+12,$Y16+$T16*12-1))-MAX(TahunBuku*12+1,$Y16)+1),0)) | AG16: =IF($B16="","",IF(OR($S16="Garis Lurus",$S16="Saldo Menurun",$S16="Unit Produksi"),MAX(0,MIN($Z16,IF($S16="Unit Produksi",TahunBuku*12+12,MIN(TahunBuku*12+12,$Y16+$T16*12-1)))-MAX(TahunBuku*12+1,$Y16)+1),0)) | AH16: =IF($B16="","",IFERROR(IF($W16="Garis Lurus",$G16*(1-MIN($V16*12,MAX(0,TahunBuku*12-$Y16+1))/($V16*12)),IF($W16="Saldo Menurun",IF(TahunBuku-1<YEAR($F16),$G16,IF(TahunBuku-1>=INT(($Y16+$V16*12-2)/12),0,$G16*(1-2/$V16*(13-MONTH($F16))/12)*(1-2/$V16)^(TahunBuku-1-YEAR($F16)))),$G16)),$G16)) | AI16: =IF($B16="","",IFERROR(IF($W16="Garis Lurus",$G16*(1-MIN($V16*12,MAX(0,TahunBuku*12+12-$Y16+1))/($V16*12)),IF($W16="Saldo Menurun",IF(TahunBuku<YEAR($F16),$G16,IF(TahunBuku>=INT(($Y16+$V16*12-2)/12),0,$G16*(1-2/$V16*(13-MONTH($F16))/12)*(1-2/$V16)^(TahunBuku-YEAR($F16)))),$G16)),$G16)) | AJ16: =IF($B16="","",IF(OR($W16="Garis Lurus",$W16="Saldo Menurun"),MAX(0,MIN(TahunBuku*12+12,$Y16+$V16*12-1)-MAX(TahunBuku*12+1,$Y16)+1),0)) | AK16: =IF($B16="","",IF(OR($W16="Garis Lurus",$W16="Saldo Menurun"),MAX(0,MIN($Z16,TahunBuku*12+12,$Y16+$V16*12-1)-MAX(TahunBuku*12+1,$Y16)+1),0)) | AL16: =IF($B16="","",$G16*$AA16) | AM16: =IF($B16="","",$G16*$AB16) | AN16: =IF($B16="","",$G16*$AC16) | AO16: =IF($B16="","",AL16+AM16-AN16) | AP16: =IF($B16="","",($G16-$AD16)*$AA16) | AQ16: =IF($B16="","",IF($AF16=0,0,($AD16-$AE16)*$AG16/$AF16)*MAX($AA16,$AB16)) | AR16: =IF($B16="","",(AP16+AQ16)*$AC16) | AS16: =IF($B16="","",AP16+AQ16-AR16) | AT16: =IF($B16="","",AO16-AS16) | AU16: =IF($B16="","",IF($AC16=1,N($R16)-($G16-AR16),0)) | AV16: =IF($B16="","",($G16-$AH16)*$AA16) | AW16: =IF($B16="","",IF($AJ16=0,0,($AH16-$AI16)*$AK16/$AJ16)*MAX($AA16,$AB16)) | AX16: =IF($B16="","",(AV16+AW16)*$AC16) | AY16: =IF($B16="","",AV16+AW16-AX16) | AZ16: =IF($B16="","",AO16-AY16) | BA16: =IF($B16="","",IF($AC16=1,N($R16)-($G16-AX16),0)) | BB16: =IF($B16="","",ROUND(AQ16-AW16,0)) | BC16: =IF($B16="","",ROUND(BA16-AU16,0)) | BD16: =IF($B16="","",BB16+BC16) | BE16: =IF($B16="","",ROUND(AV16-AP16,0)) | BF16: =IF($B16="","",ROUND(AT16-AZ16,0)) | BG16: =IF($B16="","",ROUND(BF16*TarifPPh,0)) | BH16: =IF($B16="","",IF($D16="","Kategori kosong",IF($F16="","Tgl perolehan kosong",IF(N($H16)>$G16,"Residu > harga perolehan",IF(AND(LEFT($U16,8)="Bangunan",$W16="Saldo Menurun"),"Bangunan wajib Garis Lurus (Ps.11 UU PPh)",IF(AND($S16="Unit Produksi",N($K16)=0),"Isi kapasitas unit",IF(AND(OR($S16="Garis Lurus",$S16="Saldo Menurun"),N($T16)<=0),"Umur komersial kosong",IF(AND(OR($W16="Garis Lurus",$W16="Saldo Menurun"),N($V16)<=0),"Masa manfaat fiskal kosong",IF(AND($Q16<>"",$Q16<$F16),"Tgl pelepasan < perolehan","OK")))))))))
